Traceback (most recent call last):
  File "C:\Users\chazi\AppData\Local\anaconda3\envs\Course46700\Lib\site-packages\jupyter_core\utils\__init__.py", line 154, in wrapped
    asyncio.get_running_loop()
RuntimeError: no running event loop

During handling of the above exception, another exception occurred:

Traceback (most recent call last):
  File "C:\Users\chazi\AppData\Local\anaconda3\envs\Course46700\Lib\site-packages\jupyter_cache\executors\utils.py", line 58, in single_nb_execution
    executenb(
  File "C:\Users\chazi\AppData\Local\anaconda3\envs\Course46700\Lib\site-packages\nbclient\client.py", line 1319, in execute
    return NotebookClient(nb=nb, resources=resources, km=km, **kwargs).execute()
           ^^^^^^^^^^^^^^^^^^^^^^^^^^^^^^^^^^^^^^^^^^^^^^^^^^^^^^^^^^^^^^^^^^^^^
  File "C:\Users\chazi\AppData\Local\anaconda3\envs\Course46700\Lib\site-packages\jupyter_core\utils\__init__.py", line 158, in wrapped
    return loop.run_until_complete(inner)
           ^^^^^^^^^^^^^^^^^^^^^^^^^^^^^^
  File "C:\Users\chazi\AppData\Local\anaconda3\envs\Course46700\Lib\asyncio\base_events.py", line 691, in run_until_complete
    return future.result()
           ^^^^^^^^^^^^^^^
  File "C:\Users\chazi\AppData\Local\anaconda3\envs\Course46700\Lib\site-packages\nbclient\client.py", line 709, in async_execute
    await self.async_execute_cell(
  File "C:\Users\chazi\AppData\Local\anaconda3\envs\Course46700\Lib\site-packages\nbclient\client.py", line 1062, in async_execute_cell
    await self._check_raise_for_error(cell, cell_index, exec_reply)
  File "C:\Users\chazi\AppData\Local\anaconda3\envs\Course46700\Lib\site-packages\nbclient\client.py", line 918, in _check_raise_for_error
    raise CellExecutionError.from_cell_and_msg(cell, exec_reply_content)
nbclient.exceptions.CellExecutionError: An error occurred while executing the following cell:
------------------
# try to access a non-existant key
d["fuel"]
------------------


[31m---------------------------------------------------------------------------[39m
[31mKeyError[39m                                  Traceback (most recent call last)
[36mCell[39m[36m [39m[32mIn[53][39m[32m, line 2[39m
[32m      1[39m [38;5;66;03m# try to access a non-existant key[39;00m
[32m----> [39m[32m2[39m d[[33m"[39m[33mfuel[39m[33m"[39m]

[31mKeyError[39m: 'fuel'

